Workbook

Sheet Dashboard
B2: WORK STUDY & TIME-MOTION ANALYSIS DASHBOARD
B4: Consolidated Gap & Utilization Analysis | Studies: UHT Cleaning Schedule · Nestamolt Filling (Nestamolt Tote Bin) · Tote Bin (Nestamolt and Milo) Work Schedule · Niro (3rd & 4th Floors)
B6: TOTAL OBSERVED TIME | D6: TOTAL PRODUCTIVE TIME | F6: TOTAL TIME LOST (Gap + Unobserved) | H6: OVERALL UTILIZATION RATE | J6: TOTAL GAP INSTANCES | L6: STUDIES ANALYSED
B7: ='Summary by Study'!B11 -> 23.166667 | D7: ='Summary by Study'!B12 -> 18.233333 | F7: ='Summary by Study'!B13 -> 2.85 | H7: ='Summary by Study'!B14 -> 78.705036 | J7: =COUNTIF('Gap Log'!B4:B9,"Gap") -> 5 | L7: 4
B11: VISUAL ANALYSIS
B50: KEY FINDINGS & RECOMMENDATIONS
B52: Highest single time loss | D52: Nestamolt Filling's study lost 120 minutes (2 hrs) of observation time because the observer was unavailable during breakfast & the Daily Operations Review (DOR). This is the single largest gap across all four studies.
B55: Best utilization | D55: Niro (3rd & 4th Floors) still has the highest utilization of the four studies (~89%) after adding its tea break (10:00-10:30) and the 10-minute gap that follows it — the only idle time recorded for this study.
B58: Recurring pattern | D58: Short 1-10 minute idle gaps appear between consecutive tasks (UHT, Nestamolt Filling, Tote Bin (Nestamolt and Milo), Niro) — typically material/tool retrieval or handover delays. Individually small, but they compound across a shift.
B61: Process discipline | D61: The 25-minute UHT gap before the CMP schedule and the 5-minute Nestamolt Filling post-break gap both point to scheduling/handover misalignment rather than worker inefficiency.
B65: CATEGORY LEGEND
C66: Productive | F66: Break | I66: Gap (idle/unrecorded) | L66: Unobserved (study missed)
B68: Navigate: Consolidated Data (raw activity log) → Summary by Study (aggregated KPIs) → Gap Log (all identified gaps with root cause & recommendation).

Sheet Consolidated Data
A1: CONSOLIDATED WORK-STUDY DATA — ALL STUDIES
A3: Study / Worker | B3: Plant / Section | C3: Activity | D3: Start | E3: End | F3: Duration (min) | G3: Category | H3: Notes
A4: UHT | B4: UHT Team | C4: Floor Cleaning | D4: 09:00 | E4: 10:00 | F4: 60 | G4: Productive
A5: UHT | B5: UHT Team | C5: Sweeping | D5: 10:00 | E5: 11:00 | F5: 60 | G5: Productive
A6: UHT | B6: UHT Team | C6: Machine Cleaning | D6: 11:00 | E6: 11:20 | F6: 20 | G6: Productive
A7: UHT | B7: UHT Team | C7: Windows Cleaning | D7: 11:20 | E7: 11:30 | F7: 10 | G7: Productive
A8: UHT | B8: UHT Team | C8: Sticker Roller Assistant | D8: 11:30 | E8: 11:45 | F8: 15 | G8: Productive
A9: UHT | B9: UHT Team | C9: Railings Cleaning | D9: 11:45 | E9: 13:00 | F9: 75 | G9: Productive
A10: UHT | B10: UHT Team | C10: Tea Break | D10: 13:00 | E10: 13:35 | F10: 35 | G10: Break
A11: UHT | B11: UHT Team | C11: Idle Gap (waiting for CMP schedule) | D11: 13:35 | E11: 14:00 | F11: 25 | G11: Gap | H11: 25-minute gap before CMP schedule starts
A12: Nestamolt Filling | B12: Nestamolt Tote Bin | C12: GSO Cleaning | D12: 06:00 | E12: 06:30 | F12: 30 | G12: Productive
A13: Nestamolt Filling | B13: Nestamolt Tote Bin | C13: Remove Stickers | D13: 06:30 | E13: 06:45 | F13: 15 | G13: Productive
A14: Nestamolt Filling | B14: Nestamolt Tote Bin | C14: Put Stickers | D14: 06:45 | E14: 07:00 | F14: 15 | G14: Productive
A15: Nestamolt Filling | B15: Nestamolt Tote Bin | C15: Study Unobserved (Breakfast & DOR in HR) | D15: 07:00 | E15: 09:00 | F15: 120 | G15: Unobserved | H15: Observer unavailable
A16: Nestamolt Filling | B16: Nestamolt Tote Bin | C16: Cleaning Machine Platforms | D16: 09:00 | E16: 10:30 | F16: 90 | G16: Productive
A17: Nestamolt Filling | B17: Nestamolt Tote Bin | C17: Crivert Measure | D17: 10:30 | E17: 12:00 | F17: 90 | G17: Productive
A18: Nestamolt Filling | B18: Nestamolt Tote Bin | C18: Tea Break | D18: 12:00 | E18: 12:30 | F18: 30 | G18: Break
A19: Nestamolt Filling | B19: Nestamolt Tote Bin | C19: Idle Gap (post tea break) | D19: 12:30 | E19: 12:35 | F19: 5 | G19: Gap | H19: 5-minute gap between tea break end and floor cleaning start
A20: Nestamolt Filling | B20: Nestamolt Tote Bin | C20: Floor Cleaning | D20: 12:35 | E20: 14:00 | F20: 85 | G20: Productive
A21: Tote Bin (Nestamolt and Milo) | B21: Not Specified | C21: Wet Mixture | D21: 08:30 | E21: 08:50 | F21: 20 | G21: Productive
A22: Tote Bin (Nestamolt and Milo) | B22: Not Specified | C22: Mopping | D22: 08:50 | E22: 09:15 | F22: 25 | G22: Productive
A23: Tote Bin (Nestamolt and Milo) | B23: Not Specified | C23: Idle Gap | D23: 09:15 | E23: 09:25 | F23: 10 | G23: Gap | H23: Unrecorded idle time between tasks
A24: Tote Bin (Nestamolt and Milo) | B24: Not Specified | C24: Outside Machine Cleaning | D24: 09:25 | E24: 09:40 | F24: 15 | G24: Productive
A25: Tote Bin (Nestamolt and Milo) | B25: Not Specified | C25: Gap Cleaning (task name) | D25: 09:40 | E25: 10:15 | F25: 35 | G25: Productive | H25: Task literally named 'Gap Cleaning' - not an idle gap
A26: Tote Bin (Nestamolt and Milo) | B26: Not Specified | C26: Staircase Mopping & Hand Rails Cleaning | D26: 10:15 | E26: 10:40 | F26: 25 | G26: Productive
A27: Tote Bin (Nestamolt and Milo) | B27: Not Specified | C27: Main Door Cleaning | D27: 10:40 | E27: 10:43 | F27: 3 | G27: Productive
A28: Tote Bin (Nestamolt and Milo) | B28: Not Specified | C28: Idle Gap | D28: 10:43 | E28: 10:44 | F28: 1 | G28: Gap | H28: Micro-gap between tasks
A29: Tote Bin (Nestamolt and Milo) | B29: Not Specified | C29: Outside Dryer Cleaning | D29: 10:44 | E29: 11:00 | F29: 16 | G29: Productive
A30: Tote Bin (Nestamolt and Milo) | B30: Not Specified | C30: Waste Remove | D30: 11:00 | E30: 11:20 | F30: 20 | G30: Productive
A31: Tote Bin (Nestamolt and Milo) | B31: Not Specified | C31: Wall Clean | D31: 11:20 | E31: 11:45 | F31: 25 | G31: Productive
A32: Tote Bin (Nestamolt and Milo) | B32: Not Specified | C32: Cob Webs | D32: 11:45 | E32: 12:00 | F32: 15 | G32: Productive
A33: Tote Bin (Nestamolt and Milo) | B33: Not Specified | C33: Tea Time | D33: 12:00 | E33: 12:30 | F33: 30 | G33: Break
A34: Niro | B34: Niro 3rd & 4th Floors | C34: Floor Shoe Bench Cleaning | D34: 08:30 | E34: 08:45 | F34: 15 | G34: Productive
A35: Niro | B35: Niro 3rd & 4th Floors | C35: Lift Cleaning | D35: 08:45 | E35: 09:10 | F35: 25 | G35: Productive
A36: Niro | B36: Niro 3rd & 4th Floors | C36: Dry Cleaning | D36: 09:10 | E36: 09:30 | F36: 20 | G36: Productive
A37: Niro | B37: Niro 3rd & 4th Floors | C37: VF Machine Cleaning | D37: 09:30 | E37: 10:00 | F37: 30 | G37: Productive
A38: Niro | B38: Niro 3rd & 4th Floors | C38: Tea Break | D38: 10:00 | E38: 10:30 | F38: 30 | G38: Break
A39: Niro | B39: Niro 3rd & 4th Floors | C39: Idle Gap (post tea break) | D39: 10:30 | E39: 10:40 | F39: 10 | G39: Gap | H39: 10-minute gap between tea break end and Platform & Separator Cleaning start
A40: Niro | B40: Niro 3rd & 4th Floors | C40: Platform & Separator Cleaning | D40: 10:40 | E40: 13:10 | F40: 150 | G40: Productive
A41: Niro | B41: Niro 3rd & 4th Floors | C41: Waste Removal | D41: 13:10 | E41: 14:40 | F41: 90 | G41: Productive
...

Sheet Summary by Study
A1: SUMMARY BY STUDY — TIME ALLOCATION & UTILIZATION
A3: Study | B3: Total Observed (min) | C3: Productive (min) | D3: Break (min) | E3: Gap (min) | F3: Unobserved (min) | G3: Time Lost (min) | H3: Total Observed (hrs) | I3: Utilization % | J3: Gap Instances
A4: UHT | B4: =SUMIFS('Consolidated Data'!$F$4:$F$41,'Consolidated Data'!$A$4:$A$41,$A4) -> 300 | C4: =SUMIFS('Consolidated Data'!$F$4:$F$41,'Consolidated Data'!$A$4:$A$41,$A4,'Consolidated Data'!$G$4:$G$41,"Productive") -> 240 | D4: =SUMIFS('Consolidated Data'!$F$4:$F$41,'Consolidated Data'!$A$4:$A$41,$A4,'Consolidated Data'!$G$4:$G$41,"Break") -> 35 | E4: =SUMIFS('Consolidated Data'!$F$4:$F$41,'Consolidated Data'!$A$4:$A$41,$A4,'Consolidated Data'!$G$4:$G$41,"Gap") -> 25 | F4: =SUMIFS('Consolidated Data'!$F$4:$F$41,'Consolidated Data'!$A$4:$A$41,$A4,'Consolidated Data'!$G$4:$G$41,"Unobserved") -> 0 | G4: =E4+F4 -> 25 | H4: =B4/60 -> 5 | I4: =IFERROR(C4/B4,0) -> 0.8 | J4: =COUNTIFS('Consolidated Data'!$A$4:$A$41,$A4,'Consolidated Data'!$G$4:$G$41,"Gap") -> 1
A5: Nestamolt Filling | B5: =SUMIFS('Consolidated Data'!$F$4:$F$41,'Consolidated Data'!$A$4:$A$41,$A5) -> 480 | C5: =SUMIFS('Consolidated Data'!$F$4:$F$41,'Consolidated Data'!$A$4:$A$41,$A5,'Consolidated Data'!$G$4:$G$41,"Productive") -> 325 | D5: =SUMIFS('Consolidated Data'!$F$4:$F$41,'Consolidated Data'!$A$4:$A$41,$A5,'Consolidated Data'!$G$4:$G$41,"Break") -> 30 | E5: =SUMIFS('Consolidated Data'!$F$4:$F$41,'Consolidated Data'!$A$4:$A$41,$A5,'Consolidated Data'!$G$4:$G$41,"Gap") -> 5 | F5: =SUMIFS('Consolidated Data'!$F$4:$F$41,'Consolidated Data'!$A$4:$A$41,$A5,'Consolidated Data'!$G$4:$G$41,"Unobserved") -> 120 | G5: =E5+F5 -> 125 | H5: =B5/60 -> 8 | I5: =IFERROR(C5/B5,0) -> 0.67708333 | J5: =COUNTIFS('Consolidated Data'!$A$4:$A$41,$A5,'Consolidated Data'!$G$4:$G$41,"Gap") -> 1
A6: Tote Bin (Nestamolt and Milo) | B6: =SUMIFS('Consolidated Data'!$F$4:$F$41,'Consolidated Data'!$A$4:$A$41,$A6) -> 240 | C6: =SUMIFS('Consolidated Data'!$F$4:$F$41,'Consolidated Data'!$A$4:$A$41,$A6,'Consolidated Data'!$G$4:$G$41,"Productive") -> 199 | D6: =SUMIFS('Consolidated Data'!$F$4:$F$41,'Consolidated Data'!$A$4:$A$41,$A6,'Consolidated Data'!$G$4:$G$41,"Break") -> 30 | E6: =SUMIFS('Consolidated Data'!$F$4:$F$41,'Consolidated Data'!$A$4:$A$41,$A6,'Consolidated Data'!$G$4:$G$41,"Gap") -> 11 | F6: =SUMIFS('Consolidated Data'!$F$4:$F$41,'Consolidated Data'!$A$4:$A$41,$A6,'Consolidated Data'!$G$4:$G$41,"Unobserved") -> 0 | G6: =E6+F6 -> 11 | H6: =B6/60 -> 4 | I6: =IFERROR(C6/B6,0) -> 0.82916667 | J6: =COUNTIFS('Consolidated Data'!$A$4:$A$41,$A6,'Consolidated Data'!$G$4:$G$41,"Gap") -> 2
A7: Niro | B7: =SUMIFS('Consolidated Data'!$F$4:$F$41,'Consolidated Data'!$A$4:$A$41,$A7) -> 370 | C7: =SUMIFS('Consolidated Data'!$F$4:$F$41,'Consolidated Data'!$A$4:$A$41,$A7,'Consolidated Data'!$G$4:$G$41,"Productive") -> 330 | D7: =SUMIFS('Consolidated Data'!$F$4:$F$41,'Consolidated Data'!$A$4:$A$41,$A7,'Consolidated Data'!$G$4:$G$41,"Break") -> 30 | E7: =SUMIFS('Consolidated Data'!$F$4:$F$41,'Consolidated Data'!$A$4:$A$41,$A7,'Consolidated Data'!$G$4:$G$41,"Gap") -> 10 | F7: =SUMIFS('Consolidated Data'!$F$4:$F$41,'Consolidated Data'!$A$4:$A$41,$A7,'Consolidated Data'!$G$4:$G$41,"Unobserved") -> 0 | G7: =E7+F7 -> 10 | H7: =B7/60 -> 6.1666667 | I7: =IFERROR(C7/B7,0) -> 0.89189189 | J7: =COUNTIFS('Consolidated Data'!$A$4:$A$41,$A7,'Consolidated Data'!$G$4:$G$41,"Gap") -> 1
A8: TOTAL / OVERALL | B8: =SUM(B4:B7) -> 1390 | C8: =SUM(C4:C7) -> 1094 | D8: =SUM(D4:D7) -> 125 | E8: =SUM(E4:E7) -> 51 | F8: =SUM(F4:F7) -> 120 | G8: =SUM(G4:G7) -> 171 | H8: =SUM(H4:H7) -> 23.166667 | I8: =IFERROR(C8/B8,0) -> 0.78705036 | J8: =SUM(J4:J7) -> 5
A10: Helper values for Dashboard (hours):
A11: Total Observed (hrs) | B11: =H8 -> 23.166667
A12: Total Productive (hrs) | B12: =C8/60 -> 18.233333
A13: Total Time Lost (hrs) | B13: =G8/60 -> 2.85
A14: Overall Utilization % | B14: =I8*100 -> 78.705036
A15: Overall Category Split (helper for chart):
A16: Productive | B16: =C8 -> 1094
A17: Break | B17: =D8 -> 125
A18: Gap | B18: =E8 -> 51
A19: Unobserved | B19: =F8 -> 120

Sheet Gap Log
A1: GAP LOG — IDENTIFIED IDLE TIME, OBSERVATION GAPS & RISK FLAGS
A3: Study | B3: Gap Type | C3: Start | D3: End | E3: Duration (min) | F3: Description / Cause | G3: Recommendation
A4: UHT | B4: Gap | C4: 13:35 | D4: 14:00 | E4: 25 | F4: Idle wait before CMP schedule starts | G4: Align cleaning-team finish time with CMP schedule start to remove the idle wait
A5: Nestamolt Filling | B5: Observation Gap | C5: 07:00 | D5: 09:00 | E5: 120 | F5: No study observation recorded — observer unavailable during breakfast & DOR (Daily Operations Review) in HR | G5: Arrange observer coverage / relief during meetings and breakfast so study time is not lost
A6: Nestamolt Filling | B6: Gap | C6: 12:30 | D6: 12:35 | E6: 5 | F6: Gap between tea-break end and floor-cleaning start | G6: Standardise the break-to-task handover so work resumes immediately after breaks
A7: Tote Bin (Nestamolt and Milo) | B7: Gap | C7: 09:15 | D7: 09:25 | E7: 10 | F7: Unrecorded idle time between Mopping and Outside Machine Cleaning | G7: Investigate cause (material/tool retrieval, waiting) and tighten task sequencing
A8: Tote Bin (Nestamolt and Milo) | B8: Gap | C8: 10:43 | D8: 10:44 | E8: 1 | F8: Micro-gap between Main Door Cleaning and Outside Dryer Cleaning | G8: Negligible — monitor for recurrence across future studies
A9: Niro | B9: Gap | C9: 10:30 | D9: 10:40 | E9: 10 | F9: Idle gap between tea break end and Platform & Separator Cleaning start | G9: Standardise the break-to-task handover so work resumes promptly after the tea break
D10: TOTAL GAP/RISK TIME | E10: =SUM(E4:E9) -> 171
